<?xml version="1.0" ?>
<sdf version="1.8">
<model name='robot' canonical_link='base_link'>
	<link name='base_link'>
           <pose relative_to='__model__'>0 0 0 0 0 0</pose>
	</link>
	<link name='base_footprint'>
	   <pose relative_to='base_link'>0 0 0 0 0 0</pose>
	</link>
        <link name='chassis'>
            <pose relative_to='__model__'>0.08 0 0.08 0 0 0</pose>
            <inertial auto="true" /> 
            <visual name='visual'>
                <geometry>
                	<box>
                		<size> .34448 .193675 .0508</size>
                	</box>
                </geometry>
                    <!--let's add color to our link-->
                <material>
                <ambient>0.0 0.0 1.0 1</ambient>
                <diffuse>0.0 0.0 1.0 1</diffuse>
                <specular>0.0 0.0 1.0 1</specular>
                </material>
            </visual>
            <collision name='collision'>
            <density>.7400</density>
            <pose>0 0 0 0 0 0</pose>
                <geometry>
                    <box>
                        <size>.34448 .193675 .0508</size>
                    </box>
                </geometry>
            </collision>
    </link>
	<link name='camera_body'>
	    <pose relative_to="chassis">.18 0 0 0 0 0</pose>
	    <visual name='visual'>
		<pose>0 0 0 0 0 0</pose>
		<geometry>
		    <cylinder>
			<radius>0.01</radius>
			<length>0.05</length>
		    </cylinder>
		</geometry>
		<material>
		    <ambient>1.0 0.0 0.0 1.0</ambient>
		    <diffuse>1.0 0.0 0.0 1.0</diffuse>
		    <specular>1.0 0.0 0.0 1.0</specular>
		    <emissive>0 0 0.3 1</emissive>
		</material>
	    </visual>
	    <collision name='collision'>
		<pose>0 0 0 0 0 0</pose>
		<geometry>
		    <cylinder>
			<radius>0.01</radius>
			<length>0.05</length>
		    </cylinder>
		</geometry>
	    </collision>
	    <sensor name="camera" type="camera">
	      <camera>
		<pose>.18 0 0 0 0 0</pose>
		<horizontal_fov>1.047</horizontal_fov>
		<image>
		  <width>800</width>
		  <height>600</height>
		</image>
		<clip>
		  <near>0.1</near>
		  <far>100</far>
		</clip>
		<optical_frame_id>camera</optical_frame_id>
	      </camera>
	      <always_on>1</always_on>
	      <update_rate>30</update_rate>
	      <visualize>true</visualize>
	      <topic>camera</topic>
	      <gz_frame_id>camera_body</gz_frame_id>
	    </sensor>  
	</link>
        <link name='camera'>
            <pose relative_to="camera_body">.18 0 0 1.5708 3.141 1.5708</pose>
        </link>
        <joint name='camera_joint' type='fixed'>
            <parent>chassis</parent>
            <child>camera_body</child>
        </joint>
        <joint name='camera_optical_joint' type='fixed'>
	<parent>camera_body</parent>
            <child>camera</child>
        </joint>
        
        
        
	<link name='lidar_body'>
	    <pose relative_to="chassis">.1 0 .05 0 0 0</pose>
	    <visual name='visual'>
		<pose>0 0 0 0 0 0</pose>
		<geometry>
		    <cylinder>
			<radius>0.01</radius>
			<length>0.05</length>
		    </cylinder>
		</geometry>
		<material>
		     <ambient>0.0 1.0 0.0 1.0</ambient>
		     <diffuse>0.0 1.0 0.0 1.0</diffuse>
 		     <specular>0.0 1.0 0.0 1.0</specular>
		</material>
	    </visual>
	    <collision name='collision'>
		<pose>.1 0 .05 0 0 0</pose>
		<geometry>
		    <cylinder>
			<radius>0.01</radius>
			<length>0.05</length>
		    </cylinder>
		</geometry>
	    </collision>    
            <sensor name='gpu_lidar' type='gpu_lidar'>"
    	     <pose relative_to='lidar_frame'>0 0 .015 0 0 0</pose>
             <topic>scan</topic>
    	     <update_rate>5</update_rate>
    	     <ray>
        	  <scan>
            	      <horizontal>
                	   <samples>1080</samples>
                	   <resolution>1</resolution>
                	   <min_angle>-2.35619</min_angle>
                  	   <max_angle>2.35619</max_angle>
            	      </horizontal>
            	      <vertical>
                	   <samples>1</samples>
                	   <resolution>0.01</resolution>
                	   <min_angle>0</min_angle>
                	   <max_angle>0</max_angle>
            	     </vertical>
        	 </scan>
        	 <range>
                       <min>0.08</min>
            	       <max>10.0</max>
            	       <resolution>0.01</resolution>
        	 </range>
             </ray>
    	     <always_on>1</always_on>
    	     <visualize>true</visualize>
    	     <gz_frame_id>lidar_body</gz_frame_id>
	     </sensor> 
	</link>
        <joint name='lidar_joint' type='fixed'>
            <parent>chassis</parent>
            <child>lidar_body</child>
        </joint>
        
        
        <link name='imu_body'>
	    <pose relative_to="chassis">.1 -.05 .025 0 0 0</pose>
	    <visual name='visual'>
		<pose>0 0 0 0 0 0</pose>
		<geometry>
		    <box>
			<size> .01 .01 .001</size>
		    </box>
		</geometry>
		<material>
		     <ambient>1.0 1.0 1.0 1.0</ambient>
		     <diffuse>1.0 1.0 1.0 1.0</diffuse>
 		     <specular>1.0 1.0 1.0 1.0</specular>
		</material>
	    </visual>
	    <collision name='collision'>
		<pose>.1 -.05 .025 0 0 0</pose>
		<geometry>
		    <box>
			<size> .01 .01 .001</size>
		    </box>
		</geometry>
	    </collision>    
            <sensor name="imu_sensor" type="imu">
           	<always_on>1</always_on>
           	<update_rate>5</update_rate>
           	<visualize>true</visualize>
    	    	<topic>imu</topic>
    	    	<gz_frame_id>imu_body</gz_frame_id>
	    </sensor>
	</link>
        <joint name='imu_joint' type='fixed'>
            <parent>chassis</parent>
            <child>imu_body</child>
        </joint>
        
        
        
        <link name='gps_body'>
	    <pose relative_to="chassis">.1 .05 .025 0 0 0</pose>
	    <visual name='visual'>
		<pose>0 0 0 0 0 0</pose>
		<geometry>
		    <box>
			<size> .01 .01 .001</size>
		    </box>
		</geometry>
		<material>
		     <ambient>0 1.0 1.0 1.0</ambient>
		     <diffuse>0 1.0 1.0 1.0</diffuse>
 		     <specular>0 1.0 1.0 1.0</specular>
		</material>
	    </visual>
	    <collision name='collision'>
		<pose>.1 .05 .025 0 0 0</pose>
		<geometry>
		    <box>
			<size> .01 .01 .001</size>
		    </box>
		</geometry>
	    </collision>    
                <sensor name="navsat" type="navsat">
	      		<always_on>1</always_on>
	      		<update_rate>5</update_rate>
	      		<topic>navsat</topic>
	      		<gz_frame_id>gps_body</gz_frame_id>
	    	</sensor>
	</link>
	<joint name='gps_joint' type='fixed'>
	    <parent>chassis</parent>
	    <child>gps_body</child>
	</joint>
        
        
        

    <link name='back_left_wheel'>
    <pose relative_to="chassis">-.15 .12 0 0 0 0</pose>
    <inertial auto="true" /> 
    <visual name='visual'>
        <geometry>
            <mesh>
            	<uri> file://models/robot/meshes/wheel.dae </uri>
            	<scale>0.35 0.35 0.35</scale>
            </mesh>
        </geometry>
    </visual>
    <collision name='collision'>
    <density>1.8700</density>
        <geometry>
	    <mesh>
            	<uri> file://models/robot/meshes/wheel.dae </uri>
            	<scale>0.35 0.35 0.35</scale>
            </mesh>
        </geometry>
    </collision>
</link>
<!--The same as left wheel but with different position-->
<link name='back_right_wheel'>
<pose relative_to="chassis">-.15 -.12 0 0 0 0</pose> <!--angles are in radian-->
    <inertial auto="true" /> 
    <visual name='visual'>
	<geometry>
            <mesh>
            	<uri> file://models/robot/meshes/wheel.dae </uri>
            	<scale>0.35 0.35 0.35</scale>
            </mesh>
        </geometry>
    </visual>
    <collision name='collision'>
    <density>1.8700</density>
        <geometry>
	    <mesh>
            	<uri> file://models/robot/meshes/wheel.dae </uri>
            	<scale>0.35 0.35 0.35</scale>
            </mesh>
        </geometry>
        </collision>
    </link>
    
    <link name='front_left_wheel'>
    <pose relative_to="chassis">.15 .12 0 0 0 0</pose>
    <inertial auto="true" /> 
    <visual name='visual'>
        <geometry>
            <mesh>
            	<uri> file://models/robot/meshes/wheel.dae </uri>
            	<scale>0.35 0.35 0.35</scale>
            </mesh>
        </geometry>
    </visual>
    <collision name='collision'>
    <density>1.8700</density>
        <geometry>
	    <mesh>
            	<uri> file://models/robot/meshes/wheel.dae </uri>
            	<scale>0.35 0.35 0.35</scale>
            </mesh>
        </geometry>
    </collision>
</link>

<!--The same as left wheel but with different position-->
<link name='front_right_wheel'>
<pose relative_to="chassis">.15 -.12 0 0 0 0</pose> <!--angles are in radian-->
    <inertial auto="true" /> 
    <visual name='visual'>
	<geometry>
            <mesh>
            	<uri> file://models/robot/meshes/wheel.dae </uri>
            	<scale>0.35 0.35 0.35</scale>
            </mesh>
        </geometry>
    </visual>
    <collision name='collision'>
    <density>1.8700</density>
        <geometry>
	    <mesh>
            	<uri> file://models/robot/meshes/wheel.dae </uri>
            	<scale>0.35 0.35 0.35</scale>
            </mesh>
        </geometry>
        </collision>
    </link>
   
   
    <joint name='back_left_wheel_joint' type='revolute'>
        <pose relative_to='back_left_wheel'/>
            <parent>chassis</parent>
            <child>back_left_wheel</child>
            <axis>
                <xyz expressed_in='__model__'>0 1 0</xyz> <!--can be defined as any frame or even arbitrary frames-->
                <limit>
                    <lower>-1.79769e+308</lower>    <!--negative infinity-->
                    <upper>1.79769e+308</upper>     <!--positive infinity-->
                </limit>
            </axis>
        </joint>
    <joint name='back_right_wheel_joint' type='revolute'>
        <pose relative_to='back_right_wheel'/>
        <parent>chassis</parent>
        <child>back_right_wheel</child>
            <axis>
                <xyz expressed_in='__model__'>0 1 0</xyz>
                <limit>
                    <lower>-1.79769e+308</lower>    <!--negative infinity-->
                    <upper>1.79769e+308</upper>     <!--positive infinity-->
                </limit>
            </axis>
        </joint>
        <joint name='front_left_wheel_joint' type='revolute'>
        <pose relative_to='front_left_wheel'/>
            <parent>chassis</parent>
            <child>front_left_wheel</child>
            <axis>
                <xyz expressed_in='__model__'>0 1 0</xyz> <!--can be defined as any frame or even arbitrary frames-->
                <limit>
                    <lower>-1.79769e+308</lower>    <!--negative infinity-->
                    <upper>1.79769e+308</upper>     <!--positive infinity-->
                </limit>
            </axis>
        </joint>
    <joint name='front_right_wheel_joint' type='revolute'>
        <pose relative_to='front_right_wheel'/>
        <parent>chassis</parent>
        <child>front_right_wheel</child>
            <axis>
                <xyz expressed_in='__model__'>0 1 0</xyz>
                <limit>
                    <lower>-1.79769e+308</lower>    <!--negative infinity-->
                    <upper>1.79769e+308</upper>     <!--positive infinity-->
                </limit>
            </axis>
        </joint>
        <joint name='base_footprint_joint' type='fixed'>
        	<parent> base_link </parent>
        	<child> base_footprint </child>
        </joint>
        <joint name='chassis_joint' type='fixed'>
        	<parent> base_link </parent>
        	<child> chassis </child>
        </joint>
        
    <plugin
        filename="gz-sim-diff-drive-system"
        name="gz::sim::systems::DiffDrive">
        <left_joint>back_left_wheel_joint</left_joint>
        <right_joint>back_right_wheel_joint</right_joint>
        <left_joint>front_left_wheel_joint</left_joint>
        <right_joint>front_right_wheel_joint</right_joint>
        <wheel_separation>.3</wheel_separation>
        <wheel_radius>0.06</wheel_radius>
        <odom_publish_frequency>10</odom_publish_frequency>
        <odom_topic> odom </odom_topic>
        <topic>cmd_vel</topic>
        <frame_id> odom </frame_id>
        <child_frame_id> base_link </child_frame_id>
    </plugin>
    
</model>
</sdf>
