<?xml version="1.0" ?>
<sdf version="1.8">
    <model name='robot' canonical_link='base_link'>
        <plugin
            filename="gz-sim-diff-drive-system"
            name="gz::sim::systems::DiffDrive">
            <left_joint>left_wheel_joint</left_joint>
            <left_joint>left_front_wheel_joint</left_joint>
            <right_joint>right_wheel_joint</right_joint>
            <right_joint>right_front_wheel_joint</right_joint>
            <wheel_separation>0.3</wheel_separation>
            <wheel_radius>0.06</wheel_radius>
            <odom_publish_frequency>30</odom_publish_frequency>
            <odom_topic>odom</odom_topic>
            <topic>cmd_vel</topic>
            <frame_id>odom</frame_id>
            <child_frame_id>base_link</child_frame_id>
        </plugin>

        <link name='base_link'>
            <pose relative_to='__model__'>0 0 0 0 0 0</pose>
        </link>
        <link name='base_footprint'>
            <pose relative_to="base_link">0 0 0 0 0 0</pose>
        </link>
        <joint name='base_footprint_joint' type='fixed'>
            <parent>base_link</parent>
            <child>base_footprint</child>
        </joint>

        <!--chassis-->
        <link name='chassis'>
            <pose relative_to='base_link'>0 0 0.055 0 0 0</pose>
            <inertial> <!--inertial properties of the link mass, inertia matix-->
                <mass>2.5</mass>
                <inertia>
                    <ixx>0.014167</ixx>
                    <ixy>0</ixy>
                    <ixz>0</ixz>
                    <iyy>0.008333</iyy>
                    <iyz>0</iyz>
                    <izz>0.020833</izz>
                </inertia>
            </inertial>
            <visual name='visual'>
                <geometry>
                    <box>
                        <size>0.35 0.2 0.06</size>
                    </box>
                </geometry>
                <!--Color of the link-->
                <material>
                    <ambient>0.1 0.1 0.1 0.1</ambient>
                    <diffuse>0.2 0.2 0.2 1</diffuse>
                    <specular>0.5 0.5 0.5 1</specular>
                    <emissive>0.3 0.3 0.3 1</emissive>
                </material>
            </visual>
            <collision name='collision'>
                <geometry>
                    <box>
                        <size>0.35 0.2 0.06</size>
                    </box>
                </geometry>
            </collision>
        </link>
        <joint name='chassis_joint' type='fixed'>
            <parent>base_link</parent>
            <child>chassis</child>
        </joint>

        
        <link name='camera_body'>
            <pose relative_to="chassis">0.18 0 0.02 0 0 0</pose>
            <visual name='visual'>
                <pose>0 0 0 0 0 0</pose>
                <geometry>
                    <cylinder>
                        <radius>0.01</radius>
                        <length>0.01</length>
                    </cylinder>
                </geometry>
                <material>
                    <ambient>0.1 0 0 0.1</ambient>
                    <diffuse>0.2 0 0 1</diffuse>
                    <specular>0.5 0 0 1</specular>
                    <emissive>0.3 0 0 1</emissive>
                </material>
            </visual>
            <collision name='collision'>
                <pose>0 0 0 0 1.5707 0</pose>
                <geometry>
                    <cylinder>
                        <radius>0.01</radius>
                        <length>0.01</length>
                    </cylinder>
                </geometry>
            </collision>
            <sensor name="camera" type="camera">
              <camera>
                <pose>0 0 0 0 0 0</pose>
                <horizontal_fov>1.047</horizontal_fov>
                <image>
                  <width>640</width>
                  <height>480</height>
                </image>
                <clip>
                  <near>0.1</near>
                  <far>100</far>
                </clip>
                <optical_frame_id>camera</optical_frame_id>
              </camera>
              <always_on>1</always_on>
              <update_rate>30</update_rate>
              <visualize>true</visualize>
              <topic>camera</topic>
            </sensor>
        </link>
        <link name='camera'>
            <pose relative_to="camera_body">0 0 0 1.5708 3.141 1.5708</pose>
        </link>
        <joint name='camera_joint' type='fixed'>
            <parent>chassis</parent>
            <child>camera_body</child>
        </joint>
        <joint name='camera_optical_joint' type='fixed'>
            <parent>camera_body</parent>
            <child>camera</child>
        </joint>

        <link name='imu'>
            <pose relative_to="chassis">0.1 0.075 0.035 0 0 0</pose>
            <visual name='visual'>
                <geometry>
                    <box>
                        <size>0.015 0.015 0.003</size>
                    </box>
                </geometry>
                <material>
                    <ambient>0 0 0.1 0.1</ambient>
                    <diffuse>0 0 0.2 1</diffuse>
                    <specular>0 0 0.5 1</specular>
                    <emissive>0 0 0.3 1</emissive>
                </material>
            </visual>
            <collision name='collision'>
                <geometry>
                    <box>
                        <size>0.015 0.015 0.003</size>
                    </box>
                </geometry>
            </collision>
            <sensor name="imu_sensor" type="imu">
                <always_on>1</always_on>
                <update_rate>30</update_rate>
                <visualize>true</visualize>
                <topic>imu</topic>
                <gz_frame_id>imu</gz_frame_id>
            </sensor>
            <sensor name="magnetometer" type="magnetometer">
		  <always_on>1</always_on>
		  <update_rate>100</update_rate>
		  <visualize>true</visualize>
		  <topic>magnetometer</topic>
                  <gz_frame_id>mag</gz_frame_id>
		  <enable_metrics>true</enable_metrics>
		  <magnetometer>
		    <x>
		      <noise type="gaussian">
		        <mean>0.0</mean>
		        <stddev>0.1</stddev>
		      </noise>
		    </x>
		    <y>
		      <noise type="gaussian">
		        <mean>0.0</mean>
		        <stddev>0.1</stddev>
		      </noise>
		    </y>
		    <z>
		      <noise type="gaussian">
		        <mean>0.0</mean>
		        <stddev>0.1</stddev>
		      </noise>
		    </z>
		  </magnetometer>
		</sensor>
        </link>
        <joint name='imu_joint' type='fixed'>
            <parent>chassis</parent>
            <child>imu</child>
        </joint>

        <link name='gps'>
            <pose relative_to="chassis">0.1 -0.075 0.035 0 0 0</pose>
            <visual name='visual'>
                <geometry>
                    <box>
                        <size>0.015 0.015 0.003</size>
                    </box>
                </geometry>
                <material>
                    <ambient>0 0 0 0.1</ambient>
                    <diffuse>0 0 0 1</diffuse>
                    <specular>0 0 0 1</specular>
                    <emissive>0 0 0 1</emissive>
                </material>
            </visual>
            <collision name='collision'>
                <geometry>
                    <box>
                        <size>0.015 0.015 0.003</size>
                    </box>
                </geometry>
            </collision>
            <sensor name="navsat_sensor" type="navsat">
              <always_on>1</always_on>
              <update_rate>30</update_rate>
              <topic>navsat</topic>
              <gz_frame_id>gps</gz_frame_id>
            </sensor>
        </link>
        <joint name='gps_joint' type='fixed'>
            <parent>chassis</parent>
            <child>gps</child>
        </joint>

        <link name='left_front_wheel'>
            <pose relative_to="chassis">0.16 0.125 0 -1.5707 0 0</pose>
            <inertial>
                <mass>0.25</mass>
                <inertia>
                    <ixx>0.00083333</ixx>
                    <ixy>0</ixy>
                    <ixz>0</ixz>
                    <iyy>0.00083333</iyy>
                    <iyz>0</iyz>
                    <izz>0.00125</izz>
                </inertia>
            </inertial>
            <visual name='visual'>
                <pose>0 0 0 -1.5707 0 0</pose>
                <geometry>
                    <mesh>
                        <uri>meshes/wheel.dae</uri>
                        <scale>0.35 0.35 0.35</scale>
                    </mesh>
                </geometry>
            </visual>
            <collision name='collision'>
                <geometry>
                    <cylinder>
                        <radius>0.06</radius>
                        <length>0.03</length>
                    </cylinder>
                </geometry>
            </collision>
        </link>
        <joint name='left_front_wheel_joint' type='revolute'>
            <pose relative_to='left_front_wheel'/>
            <parent>chassis</parent>
            <child>left_front_wheel</child>
            <axis>
                <xyz expressed_in='__model__'>0 1 0</xyz> 
            <limit>
            	<lower>-1.79769e+308</lower>    <!--negative infinity-->
            	<upper>1.79769e+308</upper>     <!--positive infinity-->
            </limit>
            </axis>

        </joint>

        <!--Left wheel-->
        <link name='left_wheel'>
            <pose relative_to="chassis">-0.16 0.125 0 -1.5707 0 0</pose>
            <inertial>
                <mass>0.25</mass>
                <inertia>
                    <ixx>0.00083333</ixx>
                    <ixy>0</ixy>
                    <ixz>0</ixz>
                    <iyy>0.00083333</iyy>
                    <iyz>0</iyz>
                    <izz>0.00125</izz>
                </inertia>
            </inertial>
            <visual name='visual'>
                <pose>0 0 0 -1.5707 0 0</pose>
                <geometry>
                    <mesh>
                        <uri>meshes/wheel.dae</uri>
                        <scale>0.35 0.35 0.35</scale>
                    </mesh>
                </geometry>
            </visual>
            <collision name='collision'>
                <geometry>
                    <cylinder>
                        <radius>0.06</radius>
                        <length>0.03</length>
                    </cylinder>
                </geometry>
            </collision>
        </link>
        <joint name='left_wheel_joint' type='revolute'>
            <pose relative_to='left_wheel'/>
            <parent>chassis</parent>
            <child>left_wheel</child>
            <axis>
                <xyz expressed_in='__model__'>0 1 0</xyz> 
            <limit>
            	<lower>-1.79769e+308</lower>    <!--negative infinity-->
            	<upper>1.79769e+308</upper>     <!--positive infinity-->
            </limit>
            </axis>
        </joint>

        <link name='right_front_wheel'>
            <pose relative_to="chassis">0.16 -0.125 0 -1.5707 0 0</pose>
            <inertial>
                <mass>0.25</mass>
                <inertia>
                    <ixx>0.00083333</ixx>
                    <ixy>0</ixy>
                    <ixz>0</ixz>
                    <iyy>0.00083333</iyy>
                    <iyz>0</iyz>
                    <izz>0.00125</izz>
                </inertia>
            </inertial>
            <visual name='visual'>
                <pose>0 0 0 -1.5707 0 0</pose>
                <geometry>
                    <mesh>
                        <uri>meshes/wheel.dae</uri>
                        <scale>0.35 0.35 0.35</scale>
                    </mesh>
                </geometry>
            </visual>
            <collision name='collision'>
                <geometry>
                    <cylinder>
                        <radius>0.06</radius>
                        <length>0.03</length>
                    </cylinder>
                </geometry>
            </collision>
        </link>
        <joint name='right_front_wheel_joint' type='revolute'>
            <pose relative_to='right_front_wheel'/>
            <parent>chassis</parent>
            <child>right_front_wheel</child>
            <axis>
                <xyz expressed_in='__model__'>0 1 0</xyz>
             <limit>
            	<lower>-1.79769e+308</lower>    <!--negative infinity-->
            	<upper>1.79769e+308</upper>     <!--positive infinity-->
            </limit>
            </axis>
       </joint>

        <link name='right_wheel'>
            <pose relative_to="chassis">-0.16 -0.125 0 -1.5707 0 0</pose>
            <inertial>
                <mass>0.25</mass>
                <inertia>
                    <ixx>0.00083333</ixx>
                    <ixy>0</ixy>
                    <ixz>0</ixz>
                    <iyy>0.00083333</iyy>
                    <iyz>0</iyz>
                    <izz>0.00125</izz>
                </inertia>
            </inertial>
            <visual name='visual'>
                <pose>0 0 0 -1.5707 0 0</pose>
                <geometry>
                    <mesh>
                        <uri>meshes/wheel.dae</uri>
                        <scale>0.35 0.35 0.35</scale>
                    </mesh>
                </geometry>
            </visual>
            <collision name='collision'>
                <geometry>
                    <cylinder>
                        <radius>0.06</radius>
                        <length>0.03</length>
                    </cylinder>
                </geometry>
            </collision>
        </link>
        <joint name='right_wheel_joint' type='revolute'>
            <pose relative_to='right_wheel'/>
            <parent>chassis</parent>
            <child>right_wheel</child>
            <axis>
                <xyz expressed_in='__model__'>0 1 0</xyz>
		    <limit>
		    	<lower>-1.79769e+308</lower>    <!--negative infinity-->
		    	<upper>1.79769e+308</upper>     <!--positive infinity-->
		    </limit>
            </axis>
        </joint>
<!--
        <frame name="lidar" attached_to='lidar'>
            <pose>0.0 0.0 0.02 0 0 0</pose>
        </frame>
-->
        <link name='lidar'>
            <pose relative_to='chassis'>0.1 0 0.05 0 0 0</pose>
            <visual name='visual'>
                <geometry>
                    <cylinder>
                        <radius>0.03</radius>
                        <length>0.04</length>
                    </cylinder>
     
                </geometry>
                <material>
                    <ambient>0 0 0.1 0.1</ambient>
                    <diffuse>0 0 0.2 1</diffuse>
                    <specular>0 0 0.5 1</specular>
                    <emissive>0 0 0.3 1</emissive>
                </material>
            </visual>
            <collision name='collision'>
                <geometry>
                    <cylinder>
                        <radius>0.03</radius>
                        <length>0.04</length>
                    </cylinder>
                </geometry>
            </collision>
            <sensor name='gpu_lidar' type='gpu_lidar'>"
                <pose relative_to='lidar'>0 0 0.05 0 0 0</pose>
                <topic>scan</topic>
                <gz_frame_id>lidar</gz_frame_id>
                <update_rate>10</update_rate>
                <ray>
                    <scan>
                        <horizontal>
                            <samples>1080</samples>
                            <resolution>1</resolution>
                            <min_angle>-2.35619</min_angle>
                            <max_angle>2.35619</max_angle>
                        </horizontal>
                        <vertical>
                            <samples>1</samples>
                            <resolution>0.01</resolution>
                            <min_angle>0</min_angle>
                            <max_angle>0</max_angle>
                        </vertical>
                    </scan>
                    <range>
                        <min>0.08</min>
                        <max>10.0</max>
                        <resolution>0.01</resolution>
                    </range>
                </ray>
                <visualize>true</visualize>
            </sensor>
        </link>
        <joint name='lidar_joint' type='fixed'>
            <parent>chassis</parent>
            <child>lidar</child>
        </joint>
        <!--
        <include>
		<uri>file://models/lidar_2d_v2</uri>
      		<pose relative_to='chassis'>0 0 0.02 0 0 0</pose>
	</include>

        <joint name='lidar_joint' type='fixed'>
            <parent>chassis</parent>
            <child>lidar_2d_v2::link</child>
        </joint>
        -->
    </model>
</sdf>
